---
title: 消除异步的传染性
date: 2024-10-12T03:06:01+08:00
updated: 2024-10-14T10:59:22+08:00
dg-publish: false
---

等不了同步的函数，可以引发错误

```js
function getUser() {
  return fetch('https://api.github.com/users/wallleap')
}

function m1() {
  return getUser()
}

function m2() {
  return m1()
}

function m3() {
  return m2()
}


function main() {
  const user = m3()
  console.log(user)
}

function run(func) {
  let cache = []
  let i = 0  // 某次运行中调用 fetch 的次数
  const _originalFetch = window.fetch
  window.fetch = (...args) => {
    if (cache[i]) {
      if (cache[i].status === 'fulfilled') {
        return cache[i].data
      } else if (cache[i].status === 'rejected') {
        throw cache[i].err
      }
    }
    const result = {
      status: 'pending',
      data: null,
      err: null
    }
    cache[i++] = result
    // 发送请求
    const prom = _originalFetch(...args).then(resp => resp.json()).then(resp => {
      result.status = 'fulfilled'
      result.data = resp
    }, err => {
      result.status = 'rejected'
      result.err = err
    })
    // 报错
    throw prom
  }
  try {
    func()
  } catch (err) {
    if (err instanceof Promise) {
      const reRun = () => {
        i = 0
        func()
      }
      err.then(reRun, reRun)
    }
  }
}
run(main)
```

和 React 中 `Suspense` 组件思路相同，throw promise 异常
